nohup: ignoring input
[2023-08-25 18:16:32,222] [INFO] [real_accelerator.py:133:get_accelerator] Setting ds_accelerator to cuda (auto detect)
The following values were not passed to `accelerate launch` and had defaults used instead:
		More than one GPU was found, enabling multi-GPU training.
		If this was unintended please pass in `--num_processes=1`.
	`--dynamo_backend` was set to a value of `'no'`
To avoid this warning pass in values for each of the problematic parameters or run `accelerate config`.
WARNING:torch.distributed.run:
*****************************************
Setting OMP_NUM_THREADS environment variable for each process to be 1 in default, to avoid your system being overloaded, please further tune the variable for optimal performance in your application as needed. 
*****************************************
[2023-08-25 18:16:36,729] [INFO] [real_accelerator.py:133:get_accelerator] Setting ds_accelerator to cuda (auto detect)
[2023-08-25 18:16:36,760] [INFO] [real_accelerator.py:133:get_accelerator] Setting ds_accelerator to cuda (auto detect)
[2023-08-25 18:16:36,784] [INFO] [real_accelerator.py:133:get_accelerator] Setting ds_accelerator to cuda (auto detect)
[2023-08-25 18:16:36,789] [INFO] [real_accelerator.py:133:get_accelerator] Setting ds_accelerator to cuda (auto detect)
Traceback (most recent call last):
  File "/data/users/zhangjunlei/anaconda3/envs/open-instruct/lib/python3.10/site-packages/accelerate/utils/deepspeed.py", line 52, in __init__
    config_decoded = base64.urlsafe_b64decode(config_file_or_dict).decode("utf-8")
UnicodeDecodeError: 'utf-8' codec can't decode byte 0xfd in position 0: invalid start byte

During handling of the above exception, another exception occurred:

Traceback (most recent call last):
  File "/data/users/zhangjunlei/tyx/reward-by-prm800k/open-instruct/open_instruct/finetune.py", line 1007, in <module>
    main()
  File "/data/users/zhangjunlei/tyx/reward-by-prm800k/open-instruct/open_instruct/finetune.py", line 495, in main
    accelerator = Accelerator(
  File "/data/users/zhangjunlei/anaconda3/envs/open-instruct/lib/python3.10/site-packages/accelerate/accelerator.py", line 279, in __init__
    DeepSpeedPlugin() if os.environ.get("ACCELERATE_USE_DEEPSPEED", "false") == "true" else None
  File "<string>", line 14, in __init__
  File "/data/users/zhangjunlei/anaconda3/envs/open-instruct/lib/python3.10/site-packages/accelerate/utils/dataclasses.py", line 551, in __post_init__
    self.hf_ds_config = HfDeepSpeedConfig(self.hf_ds_config)
  File "/data/users/zhangjunlei/anaconda3/envs/open-instruct/lib/python3.10/site-packages/accelerate/utils/deepspeed.py", line 55, in __init__
    raise ValueError(
ValueError: Expected a string path to an existing deepspeed config, or a dictionary, or a base64 encoded string. Received: /ds_configs/stage3_offloading_accelerate.conf
Traceback (most recent call last):
  File "/data/users/zhangjunlei/anaconda3/envs/open-instruct/lib/python3.10/site-packages/accelerate/utils/deepspeed.py", line 52, in __init__
    config_decoded = base64.urlsafe_b64decode(config_file_or_dict).decode("utf-8")
UnicodeDecodeError: 'utf-8' codec can't decode byte 0xfd in position 0: invalid start byte

During handling of the above exception, another exception occurred:

Traceback (most recent call last):
  File "/data/users/zhangjunlei/tyx/reward-by-prm800k/open-instruct/open_instruct/finetune.py", line 1007, in <module>
    main()
  File "/data/users/zhangjunlei/tyx/reward-by-prm800k/open-instruct/open_instruct/finetune.py", line 495, in main
    accelerator = Accelerator(
  File "/data/users/zhangjunlei/anaconda3/envs/open-instruct/lib/python3.10/site-packages/accelerate/accelerator.py", line 279, in __init__
    DeepSpeedPlugin() if os.environ.get("ACCELERATE_USE_DEEPSPEED", "false") == "true" else None
  File "<string>", line 14, in __init__
  File "/data/users/zhangjunlei/anaconda3/envs/open-instruct/lib/python3.10/site-packages/accelerate/utils/dataclasses.py", line 551, in __post_init__
    self.hf_ds_config = HfDeepSpeedConfig(self.hf_ds_config)
  File "/data/users/zhangjunlei/anaconda3/envs/open-instruct/lib/python3.10/site-packages/accelerate/utils/deepspeed.py", line 55, in __init__
    raise ValueError(
ValueError: Expected a string path to an existing deepspeed config, or a dictionary, or a base64 encoded string. Received: /ds_configs/stage3_offloading_accelerate.conf
Traceback (most recent call last):
  File "/data/users/zhangjunlei/anaconda3/envs/open-instruct/lib/python3.10/site-packages/accelerate/utils/deepspeed.py", line 52, in __init__
    config_decoded = base64.urlsafe_b64decode(config_file_or_dict).decode("utf-8")
UnicodeDecodeError: 'utf-8' codec can't decode byte 0xfd in position 0: invalid start byte

During handling of the above exception, another exception occurred:

Traceback (most recent call last):
  File "/data/users/zhangjunlei/tyx/reward-by-prm800k/open-instruct/open_instruct/finetune.py", line 1007, in <module>
    main()
  File "/data/users/zhangjunlei/tyx/reward-by-prm800k/open-instruct/open_instruct/finetune.py", line 495, in main
    accelerator = Accelerator(
  File "/data/users/zhangjunlei/anaconda3/envs/open-instruct/lib/python3.10/site-packages/accelerate/accelerator.py", line 279, in __init__
    DeepSpeedPlugin() if os.environ.get("ACCELERATE_USE_DEEPSPEED", "false") == "true" else None
  File "<string>", line 14, in __init__
  File "/data/users/zhangjunlei/anaconda3/envs/open-instruct/lib/python3.10/site-packages/accelerate/utils/dataclasses.py", line 551, in __post_init__
    self.hf_ds_config = HfDeepSpeedConfig(self.hf_ds_config)
  File "/data/users/zhangjunlei/anaconda3/envs/open-instruct/lib/python3.10/site-packages/accelerate/utils/deepspeed.py", line 55, in __init__
    raise ValueError(
ValueError: Expected a string path to an existing deepspeed config, or a dictionary, or a base64 encoded string. Received: /ds_configs/stage3_offloading_accelerate.conf
Traceback (most recent call last):
  File "/data/users/zhangjunlei/anaconda3/envs/open-instruct/lib/python3.10/site-packages/accelerate/utils/deepspeed.py", line 52, in __init__
    config_decoded = base64.urlsafe_b64decode(config_file_or_dict).decode("utf-8")
UnicodeDecodeError: 'utf-8' codec can't decode byte 0xfd in position 0: invalid start byte

During handling of the above exception, another exception occurred:

Traceback (most recent call last):
  File "/data/users/zhangjunlei/tyx/reward-by-prm800k/open-instruct/open_instruct/finetune.py", line 1007, in <module>
    main()
  File "/data/users/zhangjunlei/tyx/reward-by-prm800k/open-instruct/open_instruct/finetune.py", line 495, in main
    accelerator = Accelerator(
  File "/data/users/zhangjunlei/anaconda3/envs/open-instruct/lib/python3.10/site-packages/accelerate/accelerator.py", line 279, in __init__
    DeepSpeedPlugin() if os.environ.get("ACCELERATE_USE_DEEPSPEED", "false") == "true" else None
  File "<string>", line 14, in __init__
  File "/data/users/zhangjunlei/anaconda3/envs/open-instruct/lib/python3.10/site-packages/accelerate/utils/dataclasses.py", line 551, in __post_init__
    self.hf_ds_config = HfDeepSpeedConfig(self.hf_ds_config)
  File "/data/users/zhangjunlei/anaconda3/envs/open-instruct/lib/python3.10/site-packages/accelerate/utils/deepspeed.py", line 55, in __init__
    raise ValueError(
ValueError: Expected a string path to an existing deepspeed config, or a dictionary, or a base64 encoded string. Received: /ds_configs/stage3_offloading_accelerate.conf
WARNING:torch.distributed.elastic.multiprocessing.api:Sending process 2485888 closing signal SIGTERM
ERROR:torch.distributed.elastic.multiprocessing.api:failed (exitcode: 1) local_rank: 0 (pid: 2485885) of binary: /data/users/zhangjunlei/anaconda3/envs/open-instruct/bin/python
Traceback (most recent call last):
  File "/data/users/zhangjunlei/anaconda3/envs/open-instruct/bin/accelerate", line 8, in <module>
    sys.exit(main())
  File "/data/users/zhangjunlei/anaconda3/envs/open-instruct/lib/python3.10/site-packages/accelerate/commands/accelerate_cli.py", line 45, in main
    args.func(args)
  File "/data/users/zhangjunlei/anaconda3/envs/open-instruct/lib/python3.10/site-packages/accelerate/commands/launch.py", line 964, in launch_command
    deepspeed_launcher(args)
  File "/data/users/zhangjunlei/anaconda3/envs/open-instruct/lib/python3.10/site-packages/accelerate/commands/launch.py", line 687, in deepspeed_launcher
    distrib_run.run(args)
  File "/data/users/zhangjunlei/anaconda3/envs/open-instruct/lib/python3.10/site-packages/torch/distributed/run.py", line 785, in run
    elastic_launch(
  File "/data/users/zhangjunlei/anaconda3/envs/open-instruct/lib/python3.10/site-packages/torch/distributed/launcher/api.py", line 134, in __call__
    return launch_agent(self._config, self._entrypoint, list(args))
  File "/data/users/zhangjunlei/anaconda3/envs/open-instruct/lib/python3.10/site-packages/torch/distributed/launcher/api.py", line 250, in launch_agent
    raise ChildFailedError(
torch.distributed.elastic.multiprocessing.errors.ChildFailedError: 
============================================================
/data/users/zhangjunlei/tyx/reward-by-prm800k/open-instruct/open_instruct/finetune.py FAILED
------------------------------------------------------------
Failures:
[1]:
  time      : 2023-08-25_18:16:38
  host      : a100
  rank      : 1 (local_rank: 1)
  exitcode  : 1 (pid: 2485886)
  error_file: <N/A>
  traceback : To enable traceback see: https://pytorch.org/docs/stable/elastic/errors.html
[2]:
  time      : 2023-08-25_18:16:38
  host      : a100
  rank      : 2 (local_rank: 2)
  exitcode  : 1 (pid: 2485887)
  error_file: <N/A>
  traceback : To enable traceback see: https://pytorch.org/docs/stable/elastic/errors.html
------------------------------------------------------------
Root Cause (first observed failure):
[0]:
  time      : 2023-08-25_18:16:38
  host      : a100
  rank      : 0 (local_rank: 0)
  exitcode  : 1 (pid: 2485885)
  error_file: <N/A>
  traceback : To enable traceback see: https://pytorch.org/docs/stable/elastic/errors.html
============================================================
